Workbook
Name Slicer_Cust.Name: #N/A
Name Slicer_Custo._Typ: #N/A
Name Slicer_Invoice_Typ: #N/A
Name Slicer_Month: #N/A
Name Slicer_Risk_Status: #N/A
Name Slicer_Year: #N/A

Sheet PAYMENT by SAP
B2: Customer No. | C2: Customer Name | D2: Payment Document | E2: GL Account Bank | F2: Text | G2: Receipt Date | H2: Due Date | I2: Day Past Due(hari) | J2: Curr | K2: Invoice Number | L2: Payment Amount | M2: Remark | N2: Invoice Date | O2: Origin Inv
B3: 101083 | C3: PT ARDI RESTU ARTA | D3: 1400001165 | E3: 11125421 | F3: PAID BY CMS BANK SYARIAH INDONESIA KC SURABAYA BAS | G3: 45661 | H3: 45656 | I3: 5 | J3: IDR | K3: 1800000722 | L3: 29691279 | M3: Biaya Pemusnahan Limbah FABA ex PT ARA | N3: 45626 | O3: 1800000722
B4: 101531 | C4: PT MULTIHANA KREASINDO | D4: 1400002556 | E4: 11125421 | F4: PAID BY CMS BANK SYARIAH INDONESIA KC SURABAYA BAS | G4: 45665 | H4: 45656 | I4: 9 | J4: IDR | K4: 1800000759 | L4: 6701292 | M4: Biaya Pemusnahan Limbah Non B3 - AM ex PT MHK | N4: 45626 | O4: 1800000759
B5: 100146 | C5: PT KITA MANDIRI ABADI | D5: 1400003517 | E5: 11125421 | F5: PAID BY CMS BANK SYARIAH INDONESIA KC SURABAYA BAS | G5: 45666 | H5: 45656 | I5: 10 | J5: IDR | K5: 1800000736 | L5: 13556430 | M5: Biaya Pemusnahan Limbah Resin ex PT KMA | N5: 45626 | O5: 1800000736
B6: 100028 | C6: PT BANK NEGARA INDONESIA (PERSERO) | D6: 1400004048 | E6: 11125421 | F6: PAID BY CMS BANK SYARIAH INDONESIA KC SURABAYA BAS | G6: 45667 | H6: 45687 | I6: -20 | J6: IDR | K6: 1800000779 | L6: 3343457 | M6: TAGIHAN LISTRIK BANK BNI 46_TBN_NOV 24 | N6: 45657 | O6: 1800000779
B7: 100137 | C7: PT SEMEN GRESIK | D7: 1400000000 | E7: 11121871 | F7: SWEEPING GRESIK | G7: 45667 | H7: 45737 | I7: -70 | J7: IDR | K7: 1400000522 | L7: 5000000000 | M7: PEMBAYARAN POKOK SHL GRESIK 26 SEPT 2018 | N7: 45737 | O7: 1800001507
B8: 101539 | C8: PT WAHYU SEJATI TUJUH | D8: 1400005479 | E8: 11123101 | F8: WAHYU SEJATI TUJUH | G8: 45670 | H8: 45412 | I8: 258 | J8: IDR | K8: 1800000216 | L8: 1556302 | M8: Biaya Pemusnahan Limbah Fly Ash ex PT WST | N8: 45382 | O8: 1800000216
B9: 101539 | C9: PT WAHYU SEJATI TUJUH | D9: 1400005479 | E9: 11123101 | F9: WAHYU SEJATI TUJUH | G9: 45670 | H9: 45412 | I9: 258 | J9: IDR | K9: 1800000215 | L9: 11565990 | M9: Biaya Pemusnahan Limbah Dust Aluminium ex PT WST | N9: 45382 | O9: 1800000215
B10: 100009 | C10: PT KAWASAN INDUSTRI GRESIK | D10: 1400000004 | E10: 11125421 | F10: PAID BY CMS BANK SYARIAH INDONESIA KC SURABAYA BAS | G10: 45670 | H10: 45565 | I10: 105 | J10: IDR | K10: 1800000341 | L10: 15206916 | M10: Pot. Gaji Kary. Penugasan SI - KIG 07.2024 | N10: 45535 | O10: 1800000341
B11: 100009 | C11: PT KAWASAN INDUSTRI GRESIK | D11: 1400000003 | E11: 11125421 | F11: PAID BY CMS BANK SYARIAH INDONESIA KC SURABAYA BAS | G11: 45670 | H11: 45626 | I11: 44 | J11: IDR | K11: 1800000438 | L11: 15928282 | M11: Pot. Gaji Kary. Penugasan SI - KIG 09.2024 | N11: 45596 | O11: 1800000438
B12: 100009 | C12: PT KAWASAN INDUSTRI GRESIK | D12: 1400000002 | E12: 11125421 | F12: PAID BY CMS BANK SYARIAH INDONESIA KC SURABAYA BAS | G12: 45670 | H12: 45656 | I12: 14 | J12: IDR | K12: 1800000487 | L12: 16167455 | M12: Pot. Gaji Kary. Penugasan SI - KIG 10.2024 | N12: 45626 | O12: 1800000487
B13: 100009 | C13: PT KAWASAN INDUSTRI GRESIK | D13: 1400000001 | E13: 11125421 | F13: PAID BY CMS BANK SYARIAH INDONESIA KC SURABAYA BAS | G13: 45670 | H13: 45595 | I13: 75 | J13: IDR | K13: 1800000385 | L13: 17478962 | M13: Pot. Gaji Kary. Penugasan SI - KIG 08.2024 | N13: 45565 | O13: 1800000385
B14: 101082 | C14: PT METATU NUSANTARA JAYA | D14: 1400006950 | E14: 11123101 | F14: PAID BY CMS BANK BCA RN 7100000145 | G14: 45671 | H14: 45595 | I14: 76 | J14: IDR | K14: 1800000600 | L14: 3786442 | M14: Biaya Pemusnahan Limbah SBE ex PT MNJ | N14: 45565 | O14: 1800000600
... B26: 100137 | C26: PT SEMEN GRESIK | D26: 1400000010 | E26: 11121871 | F26: SWEEPING GRESIK | G26: 45674 | H26: 45698 | I26: -24 | J26: IDR | K26: 1400000000 | L26: 5000000000 | M26: PEMBAYARAN POKOK SHL GRESIK 26 SEPT 2018 | N26: 45698 | O26: 1800001507
B27: 100144 | C27: PT SINERGI INFORMATIKA SEMEN INDONE | D27: 0100000337 | G27: 45677 | H27: 44063 | I27: 1614 | J27: IDR | K27: 1800000814 | L27: 495000 | M27: Management Fee SISI Juli 2020 | N27: 44033 | O27: 1800000814
B28: 100144 | C28: PT SINERGI INFORMATIKA SEMEN INDONE | D28: 0100000338 | G28: 45677 | H28: 44007 | I28: 1670 | J28: IDR | K28: 1800000601 | L28: 565800 | M28: Management Fee SISI Mei 2020 | N28: 43977 | O28: 1800000601
B29: 100069 | C29: PT BANK MANDIRI (PERSERO) TBK. | D29: 1400000009 | E29: 11121161 | F29: PAID BY CMS BANK MANDIRI KC GRESIK RN 2100001316 | G29: 45677 | H29: 45595 | I29: 82 | J29: IDR | K29: 1800000422 | L29: 883024 | M29: Tagihan Listrik ATM Mandiri (GUSI) - Sep 24 | N29: 45565 | O29: 1800000422
B30: 100069 | C30: PT BANK MANDIRI (PERSERO) TBK. | D30: 1400000008 | E30: 11121161 | F30: PAID BY CMS BANK MANDIRI KC GRESIK RN 2100001276 | G30: 45677 | H30: 45565 | I30: 112 | J30: IDR | K30: 1800000357 | L30: 884928 | M30: Tagihan Listrik ATM Mandiri GUSI - Agustus 24 | N30: 45535 | O30: 1800000357
B31: 101490 | C31: PT. PUTRA BIMA INTERNUSA | D31: 1400008865 | E31: 11125421 | F31: PAID BY CMS BANK SYARIAH INDONESIA KC SURABAYA BAS | G31: 45677 | H31: 45687 | I31: -10 | J31: IDR | K31: 1800000823 | L31: 923076 | M31: Biaya Pemusnahan Limbah RDF ex PT PBI | N31: 45657 | O31: 1800000823
B32: 101830 | C32: ARDIYAN JAYA TRANS, PT | D32: 1400008875 | E32: 11121161 | F32: Biaya Pemusnahan Limbah Bottom Ash ex PT AJT | G32: 45677 | H32: 45534 | I32: 125 | J32: IDR | K32: 1800000464 | L32: 2996301 | M32: Biaya Pemusnahan Limbah Bottom Ash ex PT AJT | N32: 45504 | O32: 1800000464
B33: 101830 | C33: ARDIYAN JAYA TRANS, PT | D33: 1400008878 | E33: 11121161 | F33: bayar Biaya Pemusnahan Limbah SBE ex PT AJT | G33: 45677 | H33: 45687 | I33: -17 | J33: IDR | K33: 1800000848 | L33: 3086226 | M33: Biaya Pemusnahan Limbah SBE ex PT AJT | N33: 45657 | O33: 1800000848
B34: 101830 | C34: ARDIYAN JAYA TRANS, PT | D34: 1400008876 | E34: 11121161 | F34: Biaya Pemusnahan Limbah SBE ex PT AJT | G34: 45677 | H34: 45565 | I34: 94 | J34: IDR | K34: 1800000519 | L34: 3292454 | M34: Biaya Pemusnahan Limbah SBE ex PT AJT | N34: 45535 | O34: 1800000519
B35: 101697 | C35: PT JAYA JAGAT RAYA | D35: 1400008872 | E35: 11121161 | F35: PAID BY CMS BANK MANDIRI KC GRESIK RN 7100000216 | G35: 45677 | H35: 45626 | I35: 51 | J35: IDR | K35: 1800000656 | L35: 3354087 | M35: Biaya Pemusnahan Limbah Bottom Ash ex PT JJR | N35: 45596 | O35: 1800000656
B36: 100672 | C36: PT. LEWIND | D36: 1400008877 | E36: 11121161 | F36: Bayar Biaya Pemusnahan Limbah FABA ex PT LE | G36: 45677 | H36: 45657 | I36: 3 | J36: IDR | K36: 1400182174 | L36: 4000000 | M36: Kurang Bayar Biaya Pemusnahan Limbah FABA ex PT LE | N36: 45657 | O36: 1800000265
B37: 101490 | C37: PT. PUTRA BIMA INTERNUSA | D37: 1400008871 | E37: 11125421 | F37: PAID BY CMS BANK SYARIAH INDONESIA KC SURABAYA BAS | G37: 45677 | H37: 45687 | I37: -10 | J37: IDR | K37: 1800000822 | L37: 4412028 | M37: Biaya Pemusnahan Limbah Material Rejct ex PT PBI | N37: 45657 | O37: 1800000822
B38: 101697 | C38: PT JAYA JAGAT RAYA | D38: 1400008873 | E38: 11121161 | F38: PAID BY CMS BANK MANDIRI KC GRESIK RN 7100000278 | G38: 45677 | H38: 45656 | I38: 21 | J38: IDR | K38: 1800000730 | L38: 4780215 | M38: Biaya Pemusnahan Limbah Bottom Ash ex PT JJR | N38: 45626 | O38: 1800000730
B39: 101490 | C39: PT. PUTRA BIMA INTERNUSA | D39: 1400008869 | E39: 11125421 | F39: PAID BY CMS BANK SYARIAH INDONESIA KC SURABAYA BAS | G39: 45677 | H39: 45687 | I39: -10 | J39: IDR | K39: 1800000824 | L39: 9084240 | M39: Biaya Pemusnahan Limbah Sludge IPAL ex PT PBI | N39: 45657 | O39: 1800000824
B40: 100147 | C40: PT TEKNOTAMA LINGKUNGAN INTERNUSA | D40: 1400008862 | E40: 11121161 | F40: PAID BY CMS BANK MANDIRI KC GRESIK RN 7100000236 | G40: 45677 | H40: 45656 | I40: 21 | J40: IDR | K40: 1800000750 | L40: 9567756 | M40: Biaya Pemusnahan Limbah Bottom Ash ex PT TLI | N40: 45626 | O40: 1800000750
... B47: 100126 | C47: PT TRIATA MULIA INDONESIA | D47: 1400008879 | E47: 11121161 | F47: Biaya Pemusnahan Limbah Sludge Paper ex PT TMI | G47: 45677 | H47: 45442 | I47: 230 | J47: IDR | K47: 1800000287 | L47: 112416060 | M47: Biaya Pemusnahan Limbah Sludge Paper ex PT TMI | N47: 45412 | O47: 1800000287
B48: 100144 | C48: PT SINERGI INFORMATIKA SEMEN INDONE | D48: 0100000345 | G48: 45678 | H48: 44094 | I48: 1584 | J48: IDR | K48: 1800000967 | L48: 495000 | M48: Management Fee SISI Agustus 2020 | N48: 44064 | O48: 1800000967
B49: 100144 | C49: PT SINERGI INFORMATIKA SEMEN INDONE | D49: 0100000343 | G49: 45678 | H49: 43973 | I49: 1705 | J49: IDR | K49: 1800000463 | L49: 565800 | M49: Management Fee SISI April 2020 | N49: 43943 | O49: 1800000463
B50: 100144 | C50: PT SINERGI INFORMATIKA SEMEN INDONE | D50: 0100000344 | G50: 45678 | H50: 43951 | I50: 1727 | J50: IDR | K50: 1800000357 | L50: 565800 | M50: Management Fee SISI Maret 2020 | N50: 43921 | O50: 1800000357
B51: 100144 | C51: PT SINERGI INFORMATIKA SEMEN INDONE | D51: 0100000346 | G51: 45678 | H51: 43912 | I51: 1766 | J51: IDR | K51: 1800000210 | L51: 565800 | M51: Management Fee SISI Februari 2020 | N51: 43882 | O51: 1800000210
B52: 100144 | C52: PT SINERGI INFORMATIKA SEMEN INDONE | D52: 0100000347 | G52: 45678 | H52: 44129 | I52: 1549 | J52: IDR | K52: 1800001110 | L52: 609000 | M52: Management Fee SISI September 2020 | N52: 44099 | O52: 1800001110
B53: 101539 | C53: PT WAHYU SEJATI TUJUH | D53: 1400010555 | E53: 11123101 | F53: Biaya Pemusnahan Limbah Fly Ash ex PT WST | G53: 45678 | H53: 45381 | I53: 296 | J53: IDR | K53: 1800000152 | L53: 1284129 | M53: Biaya Pemusnahan Limbah Fly Ash ex PT WST | N53: 45351 | O53: 1800000152
B54: 101539 | C54: PT WAHYU SEJATI TUJUH | D54: 1400010556 | E54: 11123101 | F54: Biaya Pemusnahan Limbah Dust Aluminium ex PT WST | G54: 45678 | H54: 45381 | I54: 296 | J54: IDR | K54: 1800000151 | L54: 21516273 | M54: Biaya Pemusnahan Limbah Dust Aluminium ex PT WST | N54: 45351 | O54: 1800000151
B55: 101083 | C55: PT ARDI RESTU ARTA | D55: 1400009679 | E55: 11125421 | F55: PAID BY CMS BANK SYARIAH INDONESIA KC SURABAYA BAS | G55: 45678 | H55: 45687 | I55: -9 | J55: IDR | K55: 1800000807 | L55: 27341631 | M55: Biaya Pemusnahan Limbah FABA ex PT ARA | N55: 45657 | O55: 1800000807
B56: 101864 | C56: PT MAKMUR JAYA BERKAT BERSAMA | D56: 1400000011 | E56: 11125421 | F56: PAID BY CMS BANK SYARIAH INDONESIA KC SURABAYA BAS | G56: 45680 | H56: 45656 | I56: 24 | J56: IDR | K56: 1800000500 | L56: 2971200 | M56: Tagihan Pengembalian Ongkos Angkut - PT MJJB | N56: 45626 | O56: 1800000500
B57: 101330 | C57: PT. CAHAYA INDAH MOJOKERTO | D57: 1400012694 | E57: 11123101 | F57: PT. CAHAYA INDAH MOJOKERTO | G57: 45680 | H57: 45656 | I57: 24 | J57: IDR | K57: 1800000726 | L57: 3476010 | M57: Biaya Pemusnahan Limbah Resin ex PT CIM | N57: 45626 | O57: 1800000726
B58: 101330 | C58: PT. CAHAYA INDAH MOJOKERTO | D58: 1400012694 | E58: 11123101 | F58: PT. CAHAYA INDAH MOJOKERTO | G58: 45680 | H58: 45656 | I58: 24 | J58: IDR | K58: 1800000725 | L58: 14318676 | M58: Biaya Pemusnahan Limbah Residu Prod ex PT CIM | N58: 45626 | O58: 1800000725
...

Sheet Detail Payment
B1: Date : | C1: =+NOW() -> 46185.381
B2: Tgl Hari Ini | C2: Mapping | E2: Risk Status
B3: =NOW() -> 46185.381 | C3: > 365 | D3: >365 | E3: High Risk +
C4: 365 | D4: 120-365 | E4: High Risk
C5: 120 | D5: 90-120 | E5: Warning +
C6: 90 | D6: 60-90 | E6: Warning
C7: 60 | D7: 30-60 | E7: Low Risk
C8: 30 | D8: 0-30 | E8: No Risk
C9: 0 | D9: Current | E9: No Risk
B10: TOTAL | E10: =SUBTOTAL(9,R13:R2411) -> 1.7686032e+12
B12: Cust. Number | C12: Cust.Name | D12: Custo. Typ | E12: Payment Document | F12: GL Account Bank | G12: Text | H12: Period | I12: Receipt Date | J12: Month | K12: Year | L12: Due Date | M12: Day Past Due | N12: Aging | O12: Risk Status | P12: Curr | Q12: Invoice Number | R12: Payment Amount | S12: Remark | T12: Invoice Date | U12: Origin Inv | V12: Invoice Typ | W12: Billing Status
B13: ='PAYMENT by SAP'!B3 -> 101083 | C13: ='PAYMENT by SAP'!C3 -> PT ARDI RESTU ARTA | D13: {=VLOOKUP($C$13:$C$2411,[1]Sheet1!$C$1:$E$376,2,0)} -> External | E13: ='PAYMENT by SAP'!D3 -> 1400001165 | F13: ='PAYMENT by SAP'!E3 -> 11125421 | G13: ='PAYMENT by SAP'!F3 -> PAID BY CMS BANK SYARIAH INDONESIA KC SURABAYA BAS | H13: =I13 -> 45661 | I13: ='PAYMENT by SAP'!G3 -> 45661 | J13: =TEXT(I13,"MMM") -> Jan | K13: =TEXT(I13,"yyy") -> 2025 | L13: ='PAYMENT by SAP'!H3 -> 45656 | M13: =I13-L13 -> 5 | N13: =IF(M13<$C$9,$D$9,IF(M13<$C$8,$D$8,IF(M13<$C$7,$D$7,IF(M13<$C$6,$D$6,IF(M13<$C$5,$D$5,IF(M13<$C$4,$D$4,IF(M13<$C$3,$D$3))))))) -> 0-30 | O13: =IF(N13=$D$3,$E$3,IF(N13=$D$4,$E$4,IF(N13=$D$5,$E$5,IF(N13=$D$6,$E$6,IF(N13=$D$7,$E$7,IF(N13=$D$8,$E$8,IF(N13=$D$9,$E$9))))))) -> No Risk | P13: ='PAYMENT by SAP'!J3 -> IDR | Q13: ='PAYMENT by SAP'!K3 -> 1800000722 | R13: ='PAYMENT by SAP'!L3 -> 29691279 | S13: ='PAYMENT by SAP'!M3 -> Biaya Pemusnahan Limbah FABA ex PT ARA | T13: ='PAYMENT by SAP'!N3 -> 45626 | U13: ='PAYMENT by SAP'!O3 -> 1800000722 | V13: AFR
B14: ='PAYMENT by SAP'!B4 -> 101531 | C14: ='PAYMENT by SAP'!C4 -> PT MULTIHANA KREASINDO | D14: External | E14: ='PAYMENT by SAP'!D4 -> 1400002556 | F14: ='PAYMENT by SAP'!E4 -> 11125421 | G14: ='PAYMENT by SAP'!F4 -> PAID BY CMS BANK SYARIAH INDONESIA KC SURABAYA BAS | H14: =I14 -> 45665 | I14: ='PAYMENT by SAP'!G4 -> 45665 | J14: =TEXT(I14,"MMM") -> Jan | K14: =TEXT(I14,"yyy") -> 2025 | L14: ='PAYMENT by SAP'!H4 -> 45656 | M14: =I14-L14 -> 9 | N14: =IF(M14<$C$9,$D$9,IF(M14<$C$8,$D$8,IF(M14<$C$7,$D$7,IF(M14<$C$6,$D$6,IF(M14<$C$5,$D$5,IF(M14<$C$4,$D$4,IF(M14<$C$3,$D$3))))))) -> 0-30 | O14: =IF(N14=$D$3,$E$3,IF(N14=$D$4,$E$4,IF(N14=$D$5,$E$5,IF(N14=$D$6,$E$6,IF(N14=$D$7,$E$7,IF(N14=$D$8,$E$8,IF(N14=$D$9,$E$9))))))) -> No Risk | P14: ='PAYMENT by SAP'!J4 -> IDR | Q14: ='PAYMENT by SAP'!K4 -> 1800000759 | R14: ='PAYMENT by SAP'!L4 -> 6701292 | S14: ='PAYMENT by SAP'!M4 -> Biaya Pemusnahan Limbah Non B3 - AM ex PT MHK | T14: ='PAYMENT by SAP'!N4 -> 45626 | U14: ='PAYMENT by SAP'!O4 -> 1800000759 | V14: AFR
B15: ='PAYMENT by SAP'!B5 -> 100146 | C15: ='PAYMENT by SAP'!C5 -> PT KITA MANDIRI ABADI | D15: External | E15: ='PAYMENT by SAP'!D5 -> 1400003517 | F15: ='PAYMENT by SAP'!E5 -> 11125421 | G15: ='PAYMENT by SAP'!F5 -> PAID BY CMS BANK SYARIAH INDONESIA KC SURABAYA BAS | H15: =I15 -> 45666 | I15: ='PAYMENT by SAP'!G5 -> 45666 | J15: =TEXT(I15,"MMM") -> Jan | K15: =TEXT(I15,"yyy") -> 2025 | L15: ='PAYMENT by SAP'!H5 -> 45656 | M15: =I15-L15 -> 10 | N15: =IF(M15<$C$9,$D$9,IF(M15<$C$8,$D$8,IF(M15<$C$7,$D$7,IF(M15<$C$6,$D$6,IF(M15<$C$5,$D$5,IF(M15<$C$4,$D$4,IF(M15<$C$3,$D$3))))))) -> 0-30 | O15: =IF(N15=$D$3,$E$3,IF(N15=$D$4,$E$4,IF(N15=$D$5,$E$5,IF(N15=$D$6,$E$6,IF(N15=$D$7,$E$7,IF(N15=$D$8,$E$8,IF(N15=$D$9,$E$9))))))) -> No Risk | P15: ='PAYMENT by SAP'!J5 -> IDR | Q15: ='PAYMENT by SAP'!K5 -> 1800000736 | R15: ='PAYMENT by SAP'!L5 -> 13556430 | S15: ='PAYMENT by SAP'!M5 -> Biaya Pemusnahan Limbah Resin ex PT KMA | T15: ='PAYMENT by SAP'!N5 -> 45626 | U15: ='PAYMENT by SAP'!O5 -> 1800000736 | V15: AFR
B16: ='PAYMENT by SAP'!B6 -> 100028 | C16: ='PAYMENT by SAP'!C6 -> PT BANK NEGARA INDONESIA (PERSERO) | D16: External | E16: ='PAYMENT by SAP'!D6 -> 1400004048 | F16: ='PAYMENT by SAP'!E6 -> 11125421 | G16: ='PAYMENT by SAP'!F6 -> PAID BY CMS BANK SYARIAH INDONESIA KC SURABAYA BAS | H16: =I16 -> 45667 | I16: ='PAYMENT by SAP'!G6 -> 45667 | J16: =TEXT(I16,"MMM") -> Jan | K16: =TEXT(I16,"yyy") -> 2025 | L16: ='PAYMENT by SAP'!H6 -> 45687 | M16: =I16-L16 -> -20 | N16: =IF(M16<$C$9,$D$9,IF(M16<$C$8,$D$8,IF(M16<$C$7,$D$7,IF(M16<$C$6,$D$6,IF(M16<$C$5,$D$5,IF(M16<$C$4,$D$4,IF(M16<$C$3,$D$3))))))) -> Current | O16: =IF(N16=$D$3,$E$3,IF(N16=$D$4,$E$4,IF(N16=$D$5,$E$5,IF(N16=$D$6,$E$6,IF(N16=$D$7,$E$7,IF(N16=$D$8,$E$8,IF(N16=$D$9,$E$9))))))) -> No Risk | P16: ='PAYMENT by SAP'!J6 -> IDR | Q16: ='PAYMENT by SAP'!K6 -> 1800000779 | R16: ='PAYMENT by SAP'!L6 -> 3343457 | S16: ='PAYMENT by SAP'!M6 -> TAGIHAN LISTRIK BANK BNI 46_TBN_NOV 24 | T16: ='PAYMENT by SAP'!N6 -> 45657 | U16: ='PAYMENT by SAP'!O6 -> 1800000779 | V16: Listrik
B17: ='PAYMENT by SAP'!B7 -> 100137 | C17: ='PAYMENT by SAP'!C7 -> PT SEMEN GRESIK | D17: Group | E17: ='PAYMENT by SAP'!D7 -> 1400000000 | F17: ='PAYMENT by SAP'!E7 -> 11121871 | G17: ='PAYMENT by SAP'!F7 -> SWEEPING GRESIK | H17: =I17 -> 45667 | I17: ='PAYMENT by SAP'!G7 -> 45667 | J17: =TEXT(I17,"MMM") -> Jan | K17: =TEXT(I17,"yyy") -> 2025 | L17: ='PAYMENT by SAP'!H7 -> 45737 | M17: =I17-L17 -> -70 | N17: =IF(M17<$C$9,$D$9,IF(M17<$C$8,$D$8,IF(M17<$C$7,$D$7,IF(M17<$C$6,$D$6,IF(M17<$C$5,$D$5,IF(M17<$C$4,$D$4,IF(M17<$C$3,$D$3))))))) -> Current | O17: =IF(N17=$D$3,$E$3,IF(N17=$D$4,$E$4,IF(N17=$D$5,$E$5,IF(N17=$D$6,$E$6,IF(N17=$D$7,$E$7,IF(N17=$D$8,$E$8,IF(N17=$D$9,$E$9))))))) -> No Risk | P17: ='PAYMENT by SAP'!J7 -> IDR | Q17: ='PAYMENT by SAP'!K7 -> 1400000522 | R17: ='PAYMENT by SAP'!L7 -> 5000000000 | S17: ='PAYMENT by SAP'!M7 -> PEMBAYARAN POKOK SHL GRESIK 26 SEPT 2018 | T17: ='PAYMENT by SAP'!N7 -> 45737 | U17: ='PAYMENT by SAP'!O7 -> 1800001507 | V17: SHL
B18: ='PAYMENT by SAP'!B8 -> 101539 | C18: ='PAYMENT by SAP'!C8 -> PT WAHYU SEJATI TUJUH | D18: External | E18: ='PAYMENT by SAP'!D8 -> 1400005479 | F18: ='PAYMENT by SAP'!E8 -> 11123101 | G18: ='PAYMENT by SAP'!F8 -> WAHYU SEJATI TUJUH | H18: =I18 -> 45670 | I18: ='PAYMENT by SAP'!G8 -> 45670 | J18: =TEXT(I18,"MMM") -> Jan | K18: =TEXT(I18,"yyy") -> 2025 | L18: ='PAYMENT by SAP'!H8 -> 45412 | M18: =I18-L18 -> 258 | N18: =IF(M18<$C$9,$D$9,IF(M18<$C$8,$D$8,IF(M18<$C$7,$D$7,IF(M18<$C$6,$D$6,IF(M18<$C$5,$D$5,IF(M18<$C$4,$D$4,IF(M18<$C$3,$D$3))))))) -> 120-365 | O18: =IF(N18=$D$3,$E$3,IF(N18=$D$4,$E$4,IF(N18=$D$5,$E$5,IF(N18=$D$6,$E$6,IF(N18=$D$7,$E$7,IF(N18=$D$8,$E$8,IF(N18=$D$9,$E$9))))))) -> High Risk | P18: ='PAYMENT by SAP'!J8 -> IDR | Q18: ='PAYMENT by SAP'!K8 -> 1800000216 | R18: ='PAYMENT by SAP'!L8 -> 1556302 | S18: ='PAYMENT by SAP'!M8 -> Biaya Pemusnahan Limbah Fly Ash ex PT WST | T18: ='PAYMENT by SAP'!N8 -> 45382 | U18: ='PAYMENT by SAP'!O8 -> 1800000216 | V18: AFR
B19: ='PAYMENT by SAP'!B9 -> 101539 | C19: ='PAYMENT by SAP'!C9 -> PT WAHYU SEJATI TUJUH | D19: External | E19: ='PAYMENT by SAP'!D9 -> 1400005479 | F19: ='PAYMENT by SAP'!E9 -> 11123101 | G19: ='PAYMENT by SAP'!F9 -> WAHYU SEJATI TUJUH | H19: =I19 -> 45670 | I19: ='PAYMENT by SAP'!G9 -> 45670 | J19: =TEXT(I19,"MMM") -> Jan | K19: =TEXT(I19,"yyy") -> 2025 | L19: ='PAYMENT by SAP'!H9 -> 45412 | M19: =I19-L19 -> 258 | N19: =IF(M19<$C$9,$D$9,IF(M19<$C$8,$D$8,IF(M19<$C$7,$D$7,IF(M19<$C$6,$D$6,IF(M19<$C$5,$D$5,IF(M19<$C$4,$D$4,IF(M19<$C$3,$D$3))))))) -> 120-365 | O19: =IF(N19=$D$3,$E$3,IF(N19=$D$4,$E$4,IF(N19=$D$5,$E$5,IF(N19=$D$6,$E$6,IF(N19=$D$7,$E$7,IF(N19=$D$8,$E$8,IF(N19=$D$9,$E$9))))))) -> High Risk | P19: ='PAYMENT by SAP'!J9 -> IDR | Q19: ='PAYMENT by SAP'!K9 -> 1800000215 | R19: ='PAYMENT by SAP'!L9 -> 11565990 | S19: ='PAYMENT by SAP'!M9 -> Biaya Pemusnahan Limbah Dust Aluminium ex PT WST | T19: ='PAYMENT by SAP'!N9 -> 45382 | U19: ='PAYMENT by SAP'!O9 -> 1800000215 | V19: AFR
B20: ='PAYMENT by SAP'!B10 -> 100009 | C20: ='PAYMENT by SAP'!C10 -> PT KAWASAN INDUSTRI GRESIK | D20: Group | E20: ='PAYMENT by SAP'!D10 -> 1400000004 | F20: ='PAYMENT by SAP'!E10 -> 11125421 | G20: ='PAYMENT by SAP'!F10 -> PAID BY CMS BANK SYARIAH INDONESIA KC SURABAYA BAS | H20: =I20 -> 45670 | I20: ='PAYMENT by SAP'!G10 -> 45670 | J20: =TEXT(I20,"MMM") -> Jan | K20: =TEXT(I20,"yyy") -> 2025 | L20: ='PAYMENT by SAP'!H10 -> 45565 | M20: =I20-L20 -> 105 | N20: =IF(M20<$C$9,$D$9,IF(M20<$C$8,$D$8,IF(M20<$C$7,$D$7,IF(M20<$C$6,$D$6,IF(M20<$C$5,$D$5,IF(M20<$C$4,$D$4,IF(M20<$C$3,$D$3))))))) -> 90-120 | O20: =IF(N20=$D$3,$E$3,IF(N20=$D$4,$E$4,IF(N20=$D$5,$E$5,IF(N20=$D$6,$E$6,IF(N20=$D$7,$E$7,IF(N20=$D$8,$E$8,IF(N20=$D$9,$E$9))))))) -> Warning + | P20: ='PAYMENT by SAP'!J10 -> IDR | Q20: ='PAYMENT by SAP'!K10 -> 1800000341 | R20: ='PAYMENT by SAP'!L10 -> 15206916 | S20: ='PAYMENT by SAP'!M10 -> Pot. Gaji Kary. Penugasan SI - KIG 07.2024 | T20: ='PAYMENT by SAP'!N10 -> 45535 | U20: ='PAYMENT by SAP'!O10 -> 1800000341 | V20: Potkar
B21: ='PAYMENT by SAP'!B11 -> 100009 | C21: ='PAYMENT by SAP'!C11 -> PT KAWASAN INDUSTRI GRESIK | D21: Group | E21: ='PAYMENT by SAP'!D11 -> 1400000003 | F21: ='PAYMENT by SAP'!E11 -> 11125421 | G21: ='PAYMENT by SAP'!F11 -> PAID BY CMS BANK SYARIAH INDONESIA KC SURABAYA BAS | H21: =I21 -> 45670 | I21: ='PAYMENT by SAP'!G11 -> 45670 | J21: =TEXT(I21,"MMM") -> Jan | K21: =TEXT(I21,"yyy") -> 2025 | L21: ='PAYMENT by SAP'!H11 -> 45626 | M21: =I21-L21 -> 44 | N21: =IF(M21<$C$9,$D$9,IF(M21<$C$8,$D$8,IF(M21<$C$7,$D$7,IF(M21<$C$6,$D$6,IF(M21<$C$5,$D$5,IF(M21<$C$4,$D$4,IF(M21<$C$3,$D$3))))))) -> 30-60 | O21: =IF(N21=$D$3,$E$3,IF(N21=$D$4,$E$4,IF(N21=$D$5,$E$5,IF(N21=$D$6,$E$6,IF(N21=$D$7,$E$7,IF(N21=$D$8,$E$8,IF(N21=$D$9,$E$9))))))) -> Low Risk | P21: ='PAYMENT by SAP'!J11 -> IDR | Q21: ='PAYMENT by SAP'!K11 -> 1800000438 | R21: ='PAYMENT by SAP'!L11 -> 15928282 | S21: ='PAYMENT by SAP'!M11 -> Pot. Gaji Kary. Penugasan SI - KIG 09.2024 | T21: ='PAYMENT by SAP'!N11 -> 45596 | U21: ='PAYMENT by SAP'!O11 -> 1800000438 | V21: Potkar
B22: ='PAYMENT by SAP'!B12 -> 100009 | C22: ='PAYMENT by SAP'!C12 -> PT KAWASAN INDUSTRI GRESIK | D22: Group | E22: ='PAYMENT by SAP'!D12 -> 1400000002 | F22: ='PAYMENT by SAP'!E12 -> 11125421 | G22: ='PAYMENT by SAP'!F12 -> PAID BY CMS BANK SYARIAH INDONESIA KC SURABAYA BAS | H22: =I22 -> 45670 | I22: ='PAYMENT by SAP'!G12 -> 45670 | J22: =TEXT(I22,"MMM") -> Jan | K22: =TEXT(I22,"yyy") -> 2025 | L22: ='PAYMENT by SAP'!H12 -> 45656 | M22: =I22-L22 -> 14 | N22: =IF(M22<$C$9,$D$9,IF(M22<$C$8,$D$8,IF(M22<$C$7,$D$7,IF(M22<$C$6,$D$6,IF(M22<$C$5,$D$5,IF(M22<$C$4,$D$4,IF(M22<$C$3,$D$3))))))) -> 0-30 | O22: =IF(N22=$D$3,$E$3,IF(N22=$D$4,$E$4,IF(N22=$D$5,$E$5,IF(N22=$D$6,$E$6,IF(N22=$D$7,$E$7,IF(N22=$D$8,$E$8,IF(N22=$D$9,$E$9))))))) -> No Risk | P22: ='PAYMENT by SAP'!J12 -> IDR | Q22: ='PAYMENT by SAP'!K12 -> 1800000487 | R22: ='PAYMENT by SAP'!L12 -> 16167455 | S22: ='PAYMENT by SAP'!M12 -> Pot. Gaji Kary. Penugasan SI - KIG 10.2024 | T22: ='PAYMENT by SAP'!N12 -> 45626 | U22: ='PAYMENT by SAP'!O12 -> 1800000487 | V22: Potkar
B23: ='PAYMENT by SAP'!B13 -> 100009 | C23: ='PAYMENT by SAP'!C13 -> PT KAWASAN INDUSTRI GRESIK | D23: Group | E23: ='PAYMENT by SAP'!D13 -> 1400000001 | F23: ='PAYMENT by SAP'!E13 -> 11125421 | G23: ='PAYMENT by SAP'!F13 -> PAID BY CMS BANK SYARIAH INDONESIA KC SURABAYA BAS | H23: =I23 -> 45670 | I23: ='PAYMENT by SAP'!G13 -> 45670 | J23: =TEXT(I23,"MMM") -> Jan | K23: =TEXT(I23,"yyy") -> 2025 | L23: ='PAYMENT by SAP'!H13 -> 45595 | M23: =I23-L23 -> 75 | N23: =IF(M23<$C$9,$D$9,IF(M23<$C$8,$D$8,IF(M23<$C$7,$D$7,IF(M23<$C$6,$D$6,IF(M23<$C$5,$D$5,IF(M23<$C$4,$D$4,IF(M23<$C$3,$D$3))))))) -> 60-90 | O23: =IF(N23=$D$3,$E$3,IF(N23=$D$4,$E$4,IF(N23=$D$5,$E$5,IF(N23=$D$6,$E$6,IF(N23=$D$7,$E$7,IF(N23=$D$8,$E$8,IF(N23=$D$9,$E$9))))))) -> Warning | P23: ='PAYMENT by SAP'!J13 -> IDR | Q23: ='PAYMENT by SAP'!K13 -> 1800000385 | R23: ='PAYMENT by SAP'!L13 -> 17478962 | S23: ='PAYMENT by SAP'!M13 -> Pot. Gaji Kary. Penugasan SI - KIG 08.2024 | T23: ='PAYMENT by SAP'!N13 -> 45565 | U23: ='PAYMENT by SAP'!O13 -> 1800000385 | V23: Potkar
B24: ='PAYMENT by SAP'!B14 -> 101082 | C24: ='PAYMENT by SAP'!C14 -> PT METATU NUSANTARA JAYA | D24: External | E24: ='PAYMENT by SAP'!D14 -> 1400006950 | F24: ='PAYMENT by SAP'!E14 -> 11123101 | G24: ='PAYMENT by SAP'!F14 -> PAID BY CMS BANK BCA RN 7100000145 | H24: =I24 -> 45671 | I24: ='PAYMENT by SAP'!G14 -> 45671 | J24: =TEXT(I24,"MMM") -> Jan | K24: =TEXT(I24,"yyy") -> 2025 | L24: ='PAYMENT by SAP'!H14 -> 45595 | M24: =I24-L24 -> 76 | N24: =IF(M24<$C$9,$D$9,IF(M24<$C$8,$D$8,IF(M24<$C$7,$D$7,IF(M24<$C$6,$D$6,IF(M24<$C$5,$D$5,IF(M24<$C$4,$D$4,IF(M24<$C$3,$D$3))))))) -> 60-90 | O24: =IF(N24=$D$3,$E$3,IF(N24=$D$4,$E$4,IF(N24=$D$5,$E$5,IF(N24=$D$6,$E$6,IF(N24=$D$7,$E$7,IF(N24=$D$8,$E$8,IF(N24=$D$9,$E$9))))))) -> Warning | P24: ='PAYMENT by SAP'!J14 -> IDR | Q24: ='PAYMENT by SAP'!K14 -> 1800000600 | R24: ='PAYMENT by SAP'!L14 -> 3786442 | S24: ='PAYMENT by SAP'!M14 -> Biaya Pemusnahan Limbah SBE ex PT MNJ | T24: ='PAYMENT by SAP'!N14 -> 45565 | U24: ='PAYMENT by SAP'!O14 -> 1800000600 | V24: AFR
B25: ='PAYMENT by SAP'!B15 -> 101082 | C25: ='PAYMENT by SAP'!C15 -> PT METATU NUSANTARA JAYA | D25: External | E25: ='PAYMENT by SAP'!D15 -> 1400006952 | F25: ='PAYMENT by SAP'!E15 -> 11123101 | G25: ='PAYMENT by SAP'!F15 -> PAID BY CMS BANK BCA RN 7100000143 | H25: =I25 -> 45671 | I25: ='PAYMENT by SAP'!G15 -> 45671 | J25: =TEXT(I25,"MMM") -> Jan | K25: =TEXT(I25,"yyy") -> 2025 | L25: ='PAYMENT by SAP'!H15 -> 45595 | M25: =I25-L25 -> 76 | N25: =IF(M25<$C$9,$D$9,IF(M25<$C$8,$D$8,IF(M25<$C$7,$D$7,IF(M25<$C$6,$D$6,IF(M25<$C$5,$D$5,IF(M25<$C$4,$D$4,IF(M25<$C$3,$D$3))))))) -> 60-90 | O25: =IF(N25=$D$3,$E$3,IF(N25=$D$4,$E$4,IF(N25=$D$5,$E$5,IF(N25=$D$6,$E$6,IF(N25=$D$7,$E$7,IF(N25=$D$8,$E$8,IF(N25=$D$9,$E$9))))))) -> Warning | P25: ='PAYMENT by SAP'!J15 -> IDR | Q25: ='PAYMENT by SAP'!K15 -> 1800000599 | R25: ='PAYMENT by SAP'!L15 -> 5574696 | S25: ='PAYMENT by SAP'!M15 -> Biaya Pemusnahan Limbah Residu Prodksi ex PT MNJ | T25: ='PAYMENT by SAP'!N15 -> 45565 | U25: ='PAYMENT by SAP'!O15 -> 1800000599 | V25: AFR
... B2411: ='PAYMENT by SAP'!B2401 -> 102009 | C2411: ='PAYMENT by SAP'!C2401 -> AKHMAD YAZID | D2411: External | E2411: ='PAYMENT by SAP'!D2401 -> 1400050951 | F2411: ='PAYMENT by SAP'!E2401 -> 11121161 | G2411: ='PAYMENT by SAP'!F2401 -> UM GS APR26 - AKHMAD YAZID | H2411: =I2411 -> 46167 | I2411: ='PAYMENT by SAP'!G2401 -> 46167 | J2411: =TEXT(I2411,"MMM") -> Mei | K2411: =TEXT(I2411,"yyy") -> 2026 | L2411: ='PAYMENT by SAP'!H2401 -> 46150 | M2411: =I2411-L2411 -> 17 | N2411: =IF(M2411<$C$9,$D$9,IF(M2411<$C$8,$D$8,IF(M2411<$C$7,$D$7,IF(M2411<$C$6,$D$6,IF(M2411<$C$5,$D$5,IF(M2411<$C$4,$D$4,IF(M2411<$C$3,$D$3))))))) -> 0-30 | O2411: =IF(N2411=$D$3,$E$3,IF(N2411=$D$4,$E$4,IF(N2411=$D$5,$E$5,IF(N2411=$D$6,$E$6,IF(N2411=$D$7,$E$7,IF(N2411=$D$8,$E$8,IF(N2411=$D$9,$E$9))))))) -> No Risk | P2411: ='PAYMENT by SAP'!J2401 -> IDR | Q2411: ='PAYMENT by SAP'!K2401 -> 1800000304 | R2411: ='PAYMENT by SAP'!L2401 -> 2000000 | S2411: ='PAYMENT by SAP'!M2401 -> PENDAPATAN GRAHA SANDIYA APRIL 2026 | T2411: ='PAYMENT by SAP'!N2401 -> 46150 | U2411: ='PAYMENT by SAP'!O2401 -> 1800000304 | V2411: Sewa

Sheet Pivot
B1: Year | C1: (Semua)
A3: 11 | B3: Month | C3: Sum of Payment Amount | D3: 17 | E3: Cust.Name | F3: Sum of Payment Amount | G3: 19 | H3: Month | I3: Average of Payment Amount | J3: 20 | K3: Risk Status | L3: Count of Invoice Number | M3: 16 | N3: Risk Status | O3: Sum of Payment Amount | P3: 1 | Q3: Aging | R3: Jumlah dari Payment Amount | T3: Mounth Over Mounth | U3: Year | V3: 2026
B4: Jan | C4: 45470378597 | E4: PT Asuransi Central Asia | F4: 25347667014 | H4: Jan | I4: 1.5056417e+08 | K4: High Risk | L4: 318 | N4: High Risk | O4: 22100130529 | Q4: 60-90 | R4: 4889532877
B5: Feb | C5: 7.2258317e+10 | E5: PT SEMEN PADANG | F5: 157234271628 | H5: Feb | I5: 2.6468248e+08 | K5: High Risk + | L5: 303 | N5: High Risk + | O5: 120262192290 | Q5: 90-120 | R5: 5190735466 | U5: Month | V5: Jumlah dari Payment Amount
B6: Mar | C6: 61768289143 | E6: PT SOLUSI BANGUN INDONESIA | F6: 321387289558 | H6: Mar | I6: 3.0730492e+08 | K6: Low Risk | L6: 210 | N6: Low Risk | O6: 42677993097 | Q6: 120-365 | R6: 22100130529 | U6: Apr | V6: 4671650398
B7: Apr | C7: 43295341727 | E7: PT SEMEN TONASA | F7: 360806428121 | H7: Apr | I7: 1.4981087e+08 | K7: Warning | L7: 157 | N7: Warning | O7: 4889532877 | Q7: 30-60 | R7: 42677993097 | U7: Mei | V7: 61827873908
B8: Jun | C8: 39845940411 | E8: PT SEMEN GRESIK | F8: 791584942588 | H8: Mei | I8: 3.5371629e+08 | K8: Warning + | L8: 154 | N8: Warning + | O8: 5190735466 | Q8: >365 | R8: 120262192290 | U8: Total Keseluruhan | V8: 66499524306
B9: Jul | C9: 469235311846 | E9: Total Keseluruhan | F9: 1656360598909 | H9: Jun | I9: 4.1506188e+08 | K9: No Risk | L9: 1257 | N9: No Risk | O9: 1.5734826e+12 | Q9: Current | R9: 463724708539
B10: Sep | C10: 213335015284 | H10: Jul | I10: 3.1282354e+09 | K10: Total Keseluruhan | L10: 2399 | N10: Total Keseluruhan | O10: 1.7686032e+12 | Q10: 0-30 | R10: 1.1097579e+12 | U10: Month over Month | V10: =(V7-V6)/V6*100% -> 12.234696
B11: Nov | C11: 105818941044 | H11: Agu | I11: 8.8695555e+08 | Q11: Total Keseluruhan | R11: 1.7686032e+12
B12: Mei | C12: 111420629886 | H12: Sep | I12: 1.3943465e+09 | K12: Presesntase Current Paid | L12: =L9/L10*100% -> 0.52396832
B13: Agu | C13: 116191177021 | H13: Okt | I13: 2.2477108e+09 | T13: Year Over Year | U13: Month | V13: Mei
B14: Okt | C14: 285459271117 | H14: Nov | I14: 7.3485376e+08
B15: Des | C15: 204504575480 | H15: Des | I15: 9.3809438e+08 | U15: Year | V15: Jumlah dari Payment Amount
B16: Total Keseluruhan | C16: 1.7686032e+12 | H16: Total Keseluruhan | I16: 7.3722517e+08 | U16: 2025 | V16: 49592755978
Q17: Month | R17: (Semua) | U17: 2026 | V17: 61827873908
Q18: Year | R18: (Semua) | U18: Total Keseluruhan | V18: 111420629886
B19: Sum of Payment Amount | C19: Month
A20: 9 | B20: Cust.Name | C20: Jan | D20: Feb | E20: Mar | F20: Apr | G20: Jun | H20: Jul | I20: Sep | J20: Nov | K20: Mei | L20: Agu | M20: Okt | N20: Des | O20: Total Keseluruhan | P20: 2 | Q20: Sum of Payment Amount | U20: Year over Year | V20: =(V17-V16)/V16*100% -> 0.2467118
B21: ABDUL MUNIF EFENDI | E21: 10000000 | O21: 10000000 | Q21: 1.7686032e+12
B22: ABDUL QOHAR | D22: 1480000 | O22: 1480000
B23: ABDURROHMAN | D23: 2000000 | K23: 9020000 | O23: 11020000 | T23: Year To Date | U23: Month | V23: (Beberapa Item)
B24: ACHMAD QHOZI | C24: 11790000 | J24: 2000000 | O24: 13790000
B25: ADI MAHENDRA | H25: 11225000 | K25: 2000000 | O25: 13225000 | U25: Year | V25: Jumlah dari Payment Amount
B26: ADITYA IQBAL MUBAROK | C26: 11925000 | J26: 2000000 | O26: 13925000 | U26: 2025 | V26: 187616572473
B27: AGUNG TJAHYONO | E27: 2000000 | O27: 2000000 | U27: 2026 | V27: 1.4659638e+11
B28: AINUR RODHIYAH | H28: 12948500 | K28: 4000000 | O28: 16948500 | U28: Total Keseluruhan | V28: 3.3421296e+11
B29: ALIFFATIKHA RIFLIANNISA | D29: 2000000 | O29: 2000000
B30: AMIN PURNAWAN | E30: 2000000 | O30: 2000000 | U30: Year to Date | V30: =(V27-V26)/V26*100% -> -0.21863841
B31: ARDIYAN JAYA TRANS, PT | C31: 9374981 | D31: 56628 | H31: 40648498 | K31: 9829402 | M31: 44119471 | O31: 104028980
B32: ARIF PURWANTO | C32: 9150000 | O32: 9150000
B33: ASIYAH | C33: 13508500 | G33: 2000000 | H33: 13079500 | K33: 2000000 | O33: 30588000
B34: BALI AGE | C34: 1722700 | O34: 1722700
B35: BAMBANG SUYANTO | E35: 2000000 | H35: 11570000 | O35: 13570000
B36: BPR Mentari Terang | C36: 31338000 | E36: 2000000 | H36: 10200000 | K36: 4000000 | O36: 47538000 | T36: Bulan | U36: Realisasi Penerimaan | V36: Target Penerimaan | W36: Difference
B37: BRILLIANT SHOFFIAWINDA SUKMA NOOR | C37: 468700 | O37: 468700 | T37: Jan | U37: =C4 -> 45470378597 | V37: 12323786908 | W37: =(U37-V37)/V37*100% -> 2.6896434
B38: BUDI UTOMO | E38: 2000000 | K38: 11660000 | O38: 13660000 | T38: Feb | U38: =C5 -> 7.2258317e+10 | V38: 25884808736 | W38: =(U38-V38)/V38*100% -> 1.7915338
B39: CAKRATEK BUANA AMERTA, PT | D39: 1185480 | O39: 1185480 | T39: Mar | U39: =C6 -> 61768289143 | V39: 32722949848 | W39: =(U39-V39)/V39*100% -> 0.88761372
B40: DANA PENSIUN SEMEN GRESIK | C40: 2899700 | D40: 502900 | E40: 1754800 | F40: 460100 | G40: 417300 | H40: 385200 | I40: 856000 | K40: 1669200 | L40: 460100 | O40: 9405300 | T40: Apr | U40: =C7 -> 43295341727 | V40: 28783651701 | W40: =(U40-V40)/V40*100% -> 0.50416431
B41: DHITA NUGRAHING RAMADHANI | C41: 12220000 | O41: 12220000 | T41: Mei | U41: =C8 -> 39845940411 | V41: 35554538011 | W41: =(U41-V41)/V41*100% -> 0.12069915
...

Sheet Dashboar AR Report
B1: PAYMENT REPORT MONITORING | Commercial Finance 2 - Section Non Cemen
D57: SUMMARY | I57: MOM | J57: : | K57: =Pivot!V10 -> 12.234696 | Q57: YOY | R57: : | S57: =Pivot!V20 -> 0.2467118 | Y57: YTD | Z57: : | AA57: =Pivot!V30 -> -0.21863841

Sheet Lembar1
B2: Row Labels | C2: Jan | D2: Feb | E2: Mar | F2: Apr | G2: May | H2: Jun | I2: Jul | J2: Aug | K2: Sep | L2: Oct | M2: Nov | N2: Dec | O2: Grand Total
B3: Penerimaan | C3: 68.979.166.558 | D3: 67.842.259.098 | E3: 77.118.749.504 | F3: 58.312.972.478 | G3: 66.719.918.896 | H3: 75.758.205.888 | I3: 363.397.776.008 | J3: 108.486.211.605 | K3: 178.846.476.899 | L3: 215.199.826.471 | M3: 93.221.734.841 | N3: 125.301.573.809 | O3: 1.499.184.872.056
B4: DS | C4: 56.655.379.651 | D4: 41.957.450.362 | E4: 44.395.799.656 | F4: 29.529.320.777 | G4: 31.165.380.885 | H4: 47.873.163.948 | I4: 34.941.260.009 | J4: 26.871.068.428 | K4: 29.514.116.026 | L4: 15.388.486.689 | M4: 19.244.694.797 | N4: 30.613.322.552 | O4: 408.149.443.780
B5: NS | C5: 12.323.786.908 | D5: 25.884.808.736 | E5: 32.722.949.848 | F5: 28.783.651.701 | G5: 35.554.538.011 | H5: 27.885.041.941 | I5: 328.456.515.999 | J5: 81.615.143.177 | K5: 149.332.360.873 | L5: 199.811.339.782 | M5: 73.977.040.044 | N5: 94.688.251.257 | O5: 1.091.035.428.276
B6: Strategic Initiative | C6: 23.415.618.682 | D6: 23.415.618.682 | E6: 23.415.618.682 | F6: 23.415.618.682 | G6: 23.415.618.682 | H6: 23.415.618.682 | I6: 23.415.618.682 | J6: 23.415.618.682 | K6: 23.415.618.682 | L6: 23.415.618.682 | M6: 23.415.618.682 | N6: 23.415.618.682 | O6: 280.987.424.180
B7: DS | C7: 19.657.285.348 | D7: 19.657.285.348 | E7: 19.657.285.348 | F7: 19.657.285.348 | G7: 19.657.285.348 | H7: 19.657.285.348 | I7: 19.657.285.348 | J7: 19.657.285.348 | K7: 19.657.285.348 | L7: 19.657.285.348 | M7: 19.657.285.348 | N7: 19.657.285.348 | O7: 235.887.424.180
B8: NS | C8: 3.758.333.333 | D8: 3.758.333.333 | E8: 3.758.333.333 | F8: 3.758.333.333 | G8: 3.758.333.333 | H8: 3.758.333.333 | I8: 3.758.333.333 | J8: 3.758.333.333 | K8: 3.758.333.333 | L8: 3.758.333.333 | M8: 3.758.333.333 | N8: 3.758.333.333 | O8: 45.100.000.000
B9: Grand Total | C9: 92.394.785.240 | D9: 91.257.877.780 | E9: 100.534.368.186 | F9: 81.728.591.160 | G9: 90.135.537.578 | H9: 99.173.824.570 | I9: 386.813.394.689 | J9: 131.901.830.287 | K9: 202.262.095.580 | L9: 238.615.445.153 | M9: 116.637.353.523 | N9: 148.717.192.491 | O9: 1.780.172.296.236
B18: Row Labels | C18: Jan | D18: Feb | E18: Mar | F18: Apr | G18: May | H18: Jun | I18: Jul | J18: Aug | K18: Sep | L18: Oct | M18: Nov | N18: Dec | O18: Grand Total
B19: Target Penerimaan NS 20026 | C19: 12.323.786.908 | D19: 25.884.808.736 | E19: 32.722.949.848 | F19: 28.783.651.701 | G19: 35.554.538.011 | H19: 27.885.041.941 | I19: 328.456.515.999 | J19: 81.615.143.177 | K19: 149.332.360.873 | L19: 199.811.339.782 | M19: 73.977.040.044 | N19: 94.688.251.257 | O19: 1.091.035.428.276
B20: Target Strategic | C20: 3.758.333.333 | D20: 3.758.333.333 | E20: 3.758.333.333 | F20: 3.758.333.333 | G20: 3.758.333.333 | H20: 3.758.333.333 | I20: 3.758.333.333 | J20: 3.758.333.333 | K20: 3.758.333.333 | L20: 3.758.333.333 | M20: 3.758.333.333 | N20: 3.758.333.333 | O20: 45.100.000.000
